<?xml version="1.0" ?>
<!-- Generated using onshape-to-robot -->
<!-- Onshape https://cad.onshape.com/documents/0c58bcddcc517424c69b8683/w/b72f1cd6e7def3c60d76894a/e/5e9ca273c7e001575724893a -->
<robot name="sj">
  <!-- Link link0 -->
  <link name="link0">
    <inertial>
      <origin xyz="-0.000309241 1.065e-09 0.0263888" rpy="0 0 0"/>
      <mass value="0.264096"/>
      <inertia ixx="0.000113185" ixy="-3e-12" ixz="1.00015e-06" iyy="0.000175727" iyz="8e-12" izz="0.000147128"/>
    </inertial>
    <!-- Part dummy_dc13_idle -->
    <visual>
      <origin xyz="-0.0155 -0 0.0345" rpy="0 -0 1.5708"/>
      <geometry>
        <mesh filename="assets/dummy_dc13_idle.stl"/>
      </geometry>
      <material name="dummy_dc13_idle_material">
        <color rgba="0.980392 0.713725 0.00392157 1"/>
      </material>
    </visual>
    <collision>
      <origin xyz="-0.0155 -0 0.0345" rpy="0 -0 1.5708"/>
      <geometry>
        <mesh filename="assets/dummy_dc13_idle.stl"/>
      </geometry>
    </collision>
    <!-- Part part_2 -->
    <visual>
      <origin xyz="-0.0155 0 0.0345" rpy="0 -0 1.5708"/>
      <geometry>
        <mesh filename="assets/part_2.stl"/>
      </geometry>
      <material name="part_2_material">
        <color rgba="0.615686 0.811765 0.929412 1"/>
      </material>
    </visual>
    <collision>
      <origin xyz="-0.0155 0 0.0345" rpy="0 -0 1.5708"/>
      <geometry>
        <mesh filename="assets/part_2.stl"/>
      </geometry>
    </collision>
  </link>
  <!-- Link link1 -->
  <link name="link1">
    <inertial>
      <origin xyz="-0.0187056 0.00052996 -0.0430186" rpy="0 0 0"/>
      <mass value="0.212381"/>
      <inertia ixx="8.77419e-05" ixy="-7.29396e-07" ixz="-8.13007e-06" iyy="0.000118352" iyz="3.16036e-07" izz="0.000120043"/>
    </inertial>
    <!-- Part part_3 -->
    <visual>
      <origin xyz="-0 0 0.0245" rpy="-3.14159 0 1.5708"/>
      <geometry>
        <mesh filename="assets/part_3.stl"/>
      </geometry>
      <material name="part_3_material">
        <color rgba="0.647059 0.647059 0.647059 1"/>
      </material>
    </visual>
    <collision>
      <origin xyz="-0 0 0.0245" rpy="-3.14159 0 1.5708"/>
      <geometry>
        <mesh filename="assets/part_3.stl"/>
      </geometry>
    </collision>
    <!-- Part dummy_dc13_idle_2 -->
    <visual>
      <origin xyz="0 -0 0.0245" rpy="-3.14159 0 1.5708"/>
      <geometry>
        <mesh filename="assets/dummy_dc13_idle__2.stl"/>
      </geometry>
      <material name="dummy_dc13_idle_2_material">
        <color rgba="0.231373 0.380392 0.705882 1"/>
      </material>
    </visual>
    <collision>
      <origin xyz="0 -0 0.0245" rpy="-3.14159 0 1.5708"/>
      <geometry>
        <mesh filename="assets/dummy_dc13_idle__2.stl"/>
      </geometry>
    </collision>
  </link>
  <!-- Link link2 -->
  <link name="link2">
    <inertial>
      <origin xyz="0.113233 -1.89231e-05 0.0241592" rpy="0 0 0"/>
      <mass value="0.122875"/>
      <inertia ixx="2.44938e-05" ixy="3.7118e-08" ixz="1.21033e-06" iyy="0.00027566" iyz="6.54e-10" izz="0.000266476"/>
    </inertial>
    <!-- Part fr12_s102_k -->
    <visual>
      <origin xyz="0.1315 -2.23277e-05 0.024544" rpy="-3.14159 1.5708 0"/>
      <geometry>
        <mesh filename="assets/fr12_s102_k.stl"/>
      </geometry>
      <material name="fr12_s102_k_material">
        <color rgba="0.647059 0.647059 0.647059 1"/>
      </material>
    </visual>
    <collision>
      <origin xyz="0.1315 -2.23277e-05 0.024544" rpy="-3.14159 1.5708 0"/>
      <geometry>
        <mesh filename="assets/fr12_s102_k.stl"/>
      </geometry>
    </collision>
    <!-- Part dummy_dc12 -->
    <visual>
      <origin xyz="0.1525 -2.23277e-05 0.004544" rpy="3.14159 0 1.5708"/>
      <geometry>
        <mesh filename="assets/dummy_dc12.stl"/>
      </geometry>
      <material name="dummy_dc12_material">
        <color rgba="0.917647 0.917647 0.917647 1"/>
      </material>
    </visual>
    <collision>
      <origin xyz="0.1525 -2.23277e-05 0.004544" rpy="3.14159 0 1.5708"/>
      <geometry>
        <mesh filename="assets/dummy_dc12.stl"/>
      </geometry>
    </collision>
    <!-- Part part_2_2 -->
    <visual>
      <origin xyz="0.14 -2.23277e-05 0.024544" rpy="-1.5708 1.5708 0"/>
      <geometry>
        <mesh filename="assets/part_2__2.stl"/>
      </geometry>
      <material name="part_2_2_material">
        <color rgba="0.615686 0.811765 0.929412 1"/>
      </material>
    </visual>
    <collision>
      <origin xyz="0.14 -2.23277e-05 0.024544" rpy="-1.5708 1.5708 0"/>
      <geometry>
        <mesh filename="assets/part_2__2.stl"/>
      </geometry>
    </collision>
    <!-- Part fr13_h101_k -->
    <visual>
      <origin xyz="-0 0 0.0245" rpy="1.5708 1.5708 0"/>
      <geometry>
        <mesh filename="assets/fr13_h101_k.stl"/>
      </geometry>
      <material name="fr13_h101_k_material">
        <color rgba="0.768627 0.886275 0.952941 1"/>
      </material>
    </visual>
    <collision>
      <origin xyz="-0 0 0.0245" rpy="1.5708 1.5708 0"/>
      <geometry>
        <mesh filename="assets/fr13_h101_k.stl"/>
      </geometry>
    </collision>
  </link>
  <!-- Link link3 -->
  <link name="link3">
    <inertial>
      <origin xyz="0.0971416 0 0.0185718" rpy="0 0 0"/>
      <mass value="0.108493"/>
      <inertia ixx="1.79972e-05" ixy="0" ixz="6.83803e-07" iyy="0.000118945" iyz="-0" izz="0.000113634"/>
    </inertial>
    <!-- Part part_2_3 -->
    <visual>
      <origin xyz="0.1025 -0 0.019" rpy="3.14159 1.5708 0"/>
      <geometry>
        <mesh filename="assets/part_2__3.stl"/>
      </geometry>
      <material name="part_2_3_material">
        <color rgba="0.917647 0.917647 0.917647 1"/>
      </material>
    </visual>
    <collision>
      <origin xyz="0.1025 -0 0.019" rpy="3.14159 1.5708 0"/>
      <geometry>
        <mesh filename="assets/part_2__3.stl"/>
      </geometry>
    </collision>
    <!-- Part dummy_dc12_2 -->
    <visual>
      <origin xyz="0.1235 0 -0.001" rpy="-3.14159 0 1.5708"/>
      <geometry>
        <mesh filename="assets/dummy_dc12.stl"/>
      </geometry>
      <material name="dummy_dc12_2_material">
        <color rgba="0.917647 0.917647 0.917647 1"/>
      </material>
    </visual>
    <collision>
      <origin xyz="0.1235 0 -0.001" rpy="-3.14159 0 1.5708"/>
      <geometry>
        <mesh filename="assets/dummy_dc12.stl"/>
      </geometry>
    </collision>
    <!-- Part fr12_h101_k -->
    <visual>
      <origin xyz="0 0 0.019" rpy="1.5708 1.5708 0"/>
      <geometry>
        <mesh filename="assets/fr12_h101_k.stl"/>
      </geometry>
      <material name="fr12_h101_k_material">
        <color rgba="0.231373 0.380392 0.705882 1"/>
      </material>
    </visual>
    <collision>
      <origin xyz="0 0 0.019" rpy="1.5708 1.5708 0"/>
      <geometry>
        <mesh filename="assets/fr12_h101_k.stl"/>
      </geometry>
    </collision>
    <!-- Part fr12_s102_k_2 -->
    <visual>
      <origin xyz="0.1025 -0 0.019" rpy="3.14159 1.5708 0"/>
      <geometry>
        <mesh filename="assets/fr12_s102_k.stl"/>
      </geometry>
      <material name="fr12_s102_k_2_material">
        <color rgba="0.647059 0.647059 0.647059 1"/>
      </material>
    </visual>
    <collision>
      <origin xyz="0.1025 -0 0.019" rpy="3.14159 1.5708 0"/>
      <geometry>
        <mesh filename="assets/fr12_s102_k.stl"/>
      </geometry>
    </collision>
  </link>
  <!-- Link link4 -->
  <link name="link4">
    <inertial>
      <origin xyz="0.0410585 -0.017802 0.01895" rpy="0 0 0"/>
      <mass value="0.0954853"/>
      <inertia ixx="2.88963e-05" ixy="3.67331e-06" ixz="1e-11" iyy="2.52627e-05" iyz="-1.1e-11" izz="3.31782e-05"/>
    </inertial>
    <!-- Part j4_j5_mirrored -->
    <visual>
      <origin xyz="0.06265 -0.0085 0.018825" rpy="0 -1.5708 0"/>
      <geometry>
        <mesh filename="assets/j4_j5_mirrored.stl"/>
      </geometry>
      <material name="j4_j5_mirrored_material">
        <color rgba="0.537255 0.854902 0.827451 1"/>
      </material>
    </visual>
    <collision>
      <origin xyz="0.06265 -0.0085 0.018825" rpy="0 -1.5708 0"/>
      <geometry>
        <mesh filename="assets/j4_j5_mirrored.stl"/>
      </geometry>
    </collision>
    <!-- Part j4_j5_mirrored_2 -->
    <visual>
      <origin xyz="0.06265 -0.0085 -0.027075" rpy="0 -1.5708 0"/>
      <geometry>
        <mesh filename="assets/j4_j5_mirrored__2.stl"/>
      </geometry>
      <material name="j4_j5_mirrored_2_material">
        <color rgba="0.537255 0.854902 0.827451 1"/>
      </material>
    </visual>
    <collision>
      <origin xyz="0.06265 -0.0085 -0.027075" rpy="0 -1.5708 0"/>
      <geometry>
        <mesh filename="assets/j4_j5_mirrored__2.stl"/>
      </geometry>
    </collision>
    <!-- Part dummy_dc12_3 -->
    <visual>
      <origin xyz="0.06265 -0.0085 0.01895" rpy="-0 1.5708 0"/>
      <geometry>
        <mesh filename="assets/dummy_dc12.stl"/>
      </geometry>
      <material name="dummy_dc12_3_material">
        <color rgba="0.917647 0.917647 0.917647 1"/>
      </material>
    </visual>
    <collision>
      <origin xyz="0.06265 -0.0085 0.01895" rpy="-0 1.5708 0"/>
      <geometry>
        <mesh filename="assets/dummy_dc12.stl"/>
      </geometry>
    </collision>
  </link>
  <!-- Link link5 -->
  <link name="link5">
    <inertial>
      <origin xyz="0.000308146 -0.000777381 -0.0297451" rpy="0 0 0"/>
      <mass value="0.0294484"/>
      <inertia ixx="1.54088e-05" ixy="-1.91104e-07" ixz="2.313e-09" iyy="9.74641e-06" iyz="-5.836e-09" izz="8.03326e-06"/>
    </inertial>
    <!-- Part p01_05_base -->
    <visual>
      <origin xyz="-0 0 -0" rpy="-3.14159 0 1.5708"/>
      <geometry>
        <mesh filename="assets/p01_05_base.stl"/>
      </geometry>
      <material name="p01_05_base_material">
        <color rgba="0.32549 0.317647 0.317647 1"/>
      </material>
    </visual>
    <collision>
      <origin xyz="-0 0 -0" rpy="-3.14159 0 1.5708"/>
      <geometry>
        <mesh filename="assets/p01_05_base.stl"/>
      </geometry>
    </collision>
    <!-- Part p01_07_body -->
    <visual>
      <origin xyz="-5e-05 0 -0" rpy="3.14159 0 1.5708"/>
      <geometry>
        <mesh filename="assets/p01_07_body.stl"/>
      </geometry>
      <material name="p01_07_body_material">
        <color rgba="0.32549 0.317647 0.317647 1"/>
      </material>
    </visual>
    <collision>
      <origin xyz="-5e-05 0 -0" rpy="3.14159 0 1.5708"/>
      <geometry>
        <mesh filename="assets/p01_07_body.stl"/>
      </geometry>
    </collision>
    <!-- Part p01_06_body_motor -->
    <visual>
      <origin xyz="5e-05 0 -0" rpy="-3.14159 0 1.5708"/>
      <geometry>
        <mesh filename="assets/p01_06_body_motor.stl"/>
      </geometry>
      <material name="p01_06_body_motor_material">
        <color rgba="0.32549 0.317647 0.317647 1"/>
      </material>
    </visual>
    <collision>
      <origin xyz="5e-05 0 -0" rpy="-3.14159 0 1.5708"/>
      <geometry>
        <mesh filename="assets/p01_06_body_motor.stl"/>
      </geometry>
    </collision>
    <!-- Part dummy_dc12_4 -->
    <visual>
      <origin xyz="-0.0228 0.0275 -0.09265" rpy="-3.14159 -0 0"/>
      <geometry>
        <mesh filename="assets/dummy_dc12__2.stl"/>
      </geometry>
      <material name="dummy_dc12_4_material">
        <color rgba="0.917647 0.917647 0.917647 1"/>
      </material>
    </visual>
    <collision>
      <origin xyz="-0.0228 0.0275 -0.09265" rpy="-3.14159 -0 0"/>
      <geometry>
        <mesh filename="assets/dummy_dc12__2.stl"/>
      </geometry>
    </collision>
  </link>
  <!-- Link link6 -->
  <link name="link6">
    <inertial>
      <origin xyz="-0.00148139 -0.0131112 -0.00445993" rpy="0 0 0"/>
      <mass value="0.00659741"/>
      <inertia ixx="2.745e-06" ixy="1.87617e-07" ixz="5.675e-09" iyy="2.4936e-07" iyz="5.7184e-08" izz="2.90928e-06"/>
    </inertial>
    <!-- Part p01_01_gearlink_motor -->
    <visual>
      <origin xyz="-0.019 0.03 -0.00385" rpy="1.5708 -0 -0"/>
      <geometry>
        <mesh filename="assets/p01_01_gearlink_motor.stl"/>
      </geometry>
      <material name="p01_01_gearlink_motor_material">
        <color rgba="0.32549 0.317647 0.317647 1"/>
      </material>
    </visual>
    <collision>
      <origin xyz="-0.019 0.03 -0.00385" rpy="1.5708 -0 -0"/>
      <geometry>
        <mesh filename="assets/p01_01_gearlink_motor.stl"/>
      </geometry>
    </collision>
  </link>
  <!-- Joint from link5 to link6 -->
  <joint name="joint_6" type="revolute">
    <origin xyz="0.00395 0.019 -0.03" rpy="1.5708 -1.22173 1.5708"/>
    <parent link="link5"/>
    <child link="link6"/>
    <axis xyz="0 0 1"/>
    <limit effort="10" velocity="10" lower="-1.0472" upper="0.349066"/>
  </joint>
  <!-- Link link7 -->
  <link name="link7">
    <inertial>
      <origin xyz="-0.0122134 0.00612548 -0.00388399" rpy="0 0 0"/>
      <mass value="0.00640183"/>
      <inertia ixx="3.95771e-07" ixy="6.43693e-07" ixz="1.7e-10" iyy="2.52036e-06" iyz="-4.27e-10" izz="2.86735e-06"/>
    </inertial>
    <!-- Part p01_02_gearlink -->
    <visual>
      <origin xyz="0.0346892 0.00759356 -0.00385" rpy="-1.5708 -0 1.22173"/>
      <geometry>
        <mesh filename="assets/p01_02_gearlink.stl"/>
      </geometry>
      <material name="p01_02_gearlink_material">
        <color rgba="0.32549 0.317647 0.317647 1"/>
      </material>
    </visual>
    <collision>
      <origin xyz="0.0346892 0.00759356 -0.00385" rpy="-1.5708 -0 1.22173"/>
      <geometry>
        <mesh filename="assets/p01_02_gearlink.stl"/>
      </geometry>
    </collision>
  </link>
  <!-- Joint from link5 to link7 -->
  <joint name="joint_6_mimic_gear" type="revolute">
    <origin xyz="-0.00395 -0.019 -0.03" rpy="-1.5708 0 1.5708"/>
    <parent link="link5"/>
    <child link="link7"/>
    <axis xyz="0 0 1"/>
    <limit effort="10" velocity="10" lower="-3.141592653589793" upper="3.141592653589793"/>
    <mimic joint="joint_6" multiplier="1.0"/>
  </joint>
  <!-- Link link9 -->
  <link name="link9">
    <inertial>
      <origin xyz="0.0234923 -0.0085505 -0.00385" rpy="0 0 0"/>
      <mass value="0.00411112"/>
      <inertia ixx="1.76756e-07" ixy="3.35759e-07" ixz="0" iyy="9.7704e-07" iyz="0" izz="1.11342e-06"/>
    </inertial>
    <!-- Part p01_03_link -->
    <visual>
      <origin xyz="0.103107 -0.0242256 -0.00385" rpy="1.5708 0 -1.91986"/>
      <geometry>
        <mesh filename="assets/p01_03_link.stl"/>
      </geometry>
      <material name="p01_03_link_material">
        <color rgba="0.32549 0.317647 0.317647 1"/>
      </material>
    </visual>
    <collision>
      <origin xyz="0.103107 -0.0242256 -0.00385" rpy="1.5708 0 -1.91986"/>
      <geometry>
        <mesh filename="assets/p01_03_link.stl"/>
      </geometry>
    </collision>
  </link>
  <!-- Link link10 -->
  <link name="link10">
    <inertial>
      <origin xyz="0.0203246 0.00182357 0.004" rpy="0 0 0"/>
      <mass value="0.0165615"/>
      <inertia ixx="8.51516e-07" ixy="2.37795e-07" ixz="-0" iyy="8.75865e-06" iyz="-0" izz="8.887e-06"/>
    </inertial>
    <!-- Part p01_04_finger -->
    <visual>
      <origin xyz="-0.090873 0.0556169 0.004" rpy="-1.5708 -0 -1.91986"/>
      <geometry>
        <mesh filename="assets/p01_04_finger.stl"/>
      </geometry>
      <material name="p01_04_finger_material">
        <color rgba="0.32549 0.317647 0.317647 1"/>
      </material>
    </visual>
    <collision>
      <origin xyz="-0.090873 0.0556169 0.004" rpy="-1.5708 -0 -1.91986"/>
      <geometry>
        <mesh filename="assets/p01_04_finger.stl"/>
      </geometry>
    </collision>
  </link>
  <!-- Link link6_2 -->
  <link name="link6_2">
    <inertial>
      <origin xyz="-0.00148139 0.0368888 -0.00445993" rpy="0 0 0"/>
      <mass value="0.00659741"/>
      <inertia ixx="2.745e-06" ixy="1.87617e-07" ixz="5.675e-09" iyy="2.4936e-07" iyz="5.7184e-08" izz="2.90928e-06"/>
    </inertial>
    <!-- Part p01_01_gearlink_motor_2 -->
    <visual>
      <origin xyz="-0.019 0.08 -0.00385" rpy="1.5708 -0 -0"/>
      <geometry>
        <mesh filename="assets/p01_01_gearlink_motor.stl"/>
      </geometry>
      <material name="p01_01_gearlink_motor_2_material">
        <color rgba="0.32549 0.317647 0.317647 1"/>
      </material>
    </visual>
    <collision>
      <origin xyz="-0.019 0.08 -0.00385" rpy="1.5708 -0 -0"/>
      <geometry>
        <mesh filename="assets/p01_01_gearlink_motor.stl"/>
      </geometry>
    </collision>
  </link>
  <!-- Joint from link10 to link6_2 -->
  <joint name="joint_6_mimic_L2" type="revolute">
    <origin xyz="-0.0258793 0.00250215 0" rpy="-3.14159 -0 3.14159"/>
    <parent link="link10"/>
    <child link="link6_2"/>
    <axis xyz="0 0 1"/>
    <limit effort="10" velocity="10" lower="-3.141592653589793" upper="3.141592653589793"/>
  </joint>
  <!-- Joint from link9 to link10 -->
  <joint name="joint_6_mimic_L3" type="revolute">
    <origin xyz="0.0469846 -0.017101 0" rpy="-3.14159 0 -1.91986"/>
    <parent link="link9"/>
    <child link="link10"/>
    <axis xyz="0 0 1"/>
    <limit effort="10" velocity="10" lower="-3.141592653589793" upper="3.141592653589793"/>
  </joint>
  <!-- Joint from link5 to link9 -->
  <joint name="joint_6_mimic_L1" type="revolute">
    <origin xyz="0.00395 0.0125 -0.0551744" rpy="1.5708 0 1.5708"/>
    <parent link="link5"/>
    <child link="link9"/>
    <axis xyz="0 0 1"/>
    <limit effort="10" velocity="10" lower="-3.141592653589793" upper="3.141592653589793"/>
  </joint>
  <!-- Link link8 -->
  <link name="link8">
    <inertial>
      <origin xyz="-0.0234923 0.0085505 -0.00385" rpy="0 0 0"/>
      <mass value="0.00411112"/>
      <inertia ixx="1.76756e-07" ixy="3.35759e-07" ixz="0" iyy="9.7704e-07" iyz="0" izz="1.11342e-06"/>
    </inertial>
    <!-- Part p01_03_link_2 -->
    <visual>
      <origin xyz="-0.0945563 0.0477179 -0.00385" rpy="-1.5708 0 -1.91986"/>
      <geometry>
        <mesh filename="assets/p01_03_link.stl"/>
      </geometry>
      <material name="p01_03_link_2_material">
        <color rgba="0.32549 0.317647 0.317647 1"/>
      </material>
    </visual>
    <collision>
      <origin xyz="-0.0945563 0.0477179 -0.00385" rpy="-1.5708 0 -1.91986"/>
      <geometry>
        <mesh filename="assets/p01_03_link.stl"/>
      </geometry>
    </collision>
  </link>
  <!-- Link link11 -->
  <link name="link11">
    <inertial>
      <origin xyz="-0.00866502 0.0184752 0.004" rpy="0 0 0"/>
      <mass value="0.0165615"/>
      <inertia ixx="7.98655e-06" ixy="2.35914e-06" ixz="0" iyy="1.62362e-06" iyz="-0" izz="8.887e-06"/>
    </inertial>
    <!-- Part p01_04_finger_2 -->
    <visual>
      <origin xyz="-0.0211824 -0.104415 0.004" rpy="-1.5708 0 -0"/>
      <geometry>
        <mesh filename="assets/p01_04_finger.stl"/>
      </geometry>
      <material name="p01_04_finger_2_material">
        <color rgba="0.32549 0.317647 0.317647 1"/>
      </material>
    </visual>
    <collision>
      <origin xyz="-0.0211824 -0.104415 0.004" rpy="-1.5708 0 -0"/>
      <geometry>
        <mesh filename="assets/p01_04_finger.stl"/>
      </geometry>
    </collision>
  </link>
  <!-- Link link7_2 -->
  <link name="link7_2">
    <inertial>
      <origin xyz="0.00157884 -0.0364281 -0.00388399" rpy="0 0 0"/>
      <mass value="0.00640183"/>
      <inertia ixx="2.68558e-06" ixy="1.89731e-07" ixz="-3.44e-10" iyy="2.30542e-07" iyz="-3.05e-10" izz="2.86735e-06"/>
    </inertial>
    <!-- Part p01_02_gearlink_2 -->
    <visual>
      <origin xyz="0.019 -0.08 -0.00385" rpy="-1.5708 0 0"/>
      <geometry>
        <mesh filename="assets/p01_02_gearlink.stl"/>
      </geometry>
      <material name="p01_02_gearlink_2_material">
        <color rgba="0.32549 0.317647 0.317647 1"/>
      </material>
    </visual>
    <collision>
      <origin xyz="0.019 -0.08 -0.00385" rpy="-1.5708 0 0"/>
      <geometry>
        <mesh filename="assets/p01_02_gearlink.stl"/>
      </geometry>
    </collision>
  </link>
  <!-- Joint from link11 to link7_2 -->
  <joint name="joint_6_mimic_R2" type="revolute">
    <origin xyz="0.0065 -0.0251744 0" rpy="3.14159 0 1.91986"/>
    <parent link="link11"/>
    <child link="link7_2"/>
    <axis xyz="0 0 1"/>
    <limit effort="10" velocity="10" lower="-3.141592653589793" upper="3.141592653589793"/>
  </joint>
  <!-- Joint from link8 to link11 -->
  <joint name="joint_6_mimic_R3" type="revolute">
    <origin xyz="-0.0469846 0.017101 0" rpy="-3.14159 -0 -3.14159"/>
    <parent link="link8"/>
    <child link="link11"/>
    <axis xyz="0 0 1"/>
    <limit effort="10" velocity="10" lower="-3.141592653589793" upper="3.141592653589793"/>
  </joint>
  <!-- Joint from link5 to link8 -->
  <joint name="joint_6_mimic_R1" type="revolute">
    <origin xyz="-0.00395 -0.0125 -0.0551744" rpy="-1.5708 0 1.5708"/>
    <parent link="link5"/>
    <child link="link8"/>
    <axis xyz="0 0 1"/>
    <limit effort="10" velocity="10" lower="-3.141592653589793" upper="3.141592653589793"/>
  </joint>
  <!-- Joint from link4 to link5 -->
  <joint name="joint_5" type="revolute">
    <origin xyz="0.06165 -0.0085 0.01895" rpy="-1.5708 -0 1.5708"/>
    <parent link="link4"/>
    <child link="link5"/>
    <axis xyz="0 0 1"/>
    <limit effort="10" velocity="10" lower="-1.5708" upper="1.5708"/>
  </joint>
  <!-- Joint from link3 to link4 -->
  <joint name="joint_4" type="revolute">
    <origin xyz="0.1235 0 -0" rpy="-0 0 0"/>
    <parent link="link3"/>
    <child link="link4"/>
    <axis xyz="0 0 1"/>
    <limit effort="10" velocity="10" lower="-0.523599" upper="1.5708"/>
  </joint>
  <!-- Joint from link2 to link3 -->
  <joint name="joint_3" type="revolute">
    <origin xyz="0.1525 -2.23277e-05 0.005544" rpy="-0 0 0"/>
    <parent link="link2"/>
    <child link="link3"/>
    <axis xyz="0 0 1"/>
    <limit effort="10" velocity="10" lower="-0.523599" upper="1.5708"/>
  </joint>
  <!-- Joint from link1 to link2 -->
  <joint name="joint_2" type="revolute">
    <origin xyz="-1.0941e-08 0.0245004 -0.0458276" rpy="1.5708 0 4.46576e-07"/>
    <parent link="link1"/>
    <child link="link2"/>
    <axis xyz="0 0 1"/>
    <limit effort="10" velocity="10" lower="-1.5708" upper="0.523599"/>
  </joint>
  <!-- Joint from link0 to link1 -->
  <joint name="joint_1" type="revolute">
    <origin xyz="-0.0155 -0 0.059" rpy="3.14159 -0 3.14159"/>
    <parent link="link0"/>
    <child link="link1"/>
    <axis xyz="0 0 1"/>
    <limit effort="10" velocity="10" lower="-1.5708" upper="1.5708"/>
  </joint>
</robot>
