#VRML_SIM R2025a utf8
# license: Apache License 2.0
# license url: http://www.apache.org/licenses/LICENSE-2.0
# This is a proto file for Webots for the Robotarm
# Extracted from: /home/sj/BOTDAE/robotarm.urdf

PROTO Robotarm [
  field  SFVec3f     translation     0 0 0
  field  SFRotation  rotation        0 0 1 0
  field  SFString    name            "Robotarm"  # Is `Robot.name`.
  field  SFString    controller      "none"          # Is `Robot.controller`.
  field  MFString    controllerArgs  []              # Is `Robot.controllerArgs`.
  field  SFString    customData      ""              # Is `Robot.customData`.
  field  SFBool      supervisor      FALSE           # Is `Robot.supervisor`.
  field  SFBool      synchronization TRUE            # Is `Robot.synchronization`.
  field  SFBool      selfCollision   FALSE           # Is `Robot.selfCollision`.
]
{
  Robot {
    translation IS translation
    rotation IS rotation
    controller IS controller
    controllerArgs IS controllerArgs
    customData IS customData
    supervisor IS supervisor
    synchronization IS synchronization
    selfCollision IS selfCollision

    children [
      Receiver {
        name "receiver"
        channel 1
      }
      
      Pose {
        translation 0.015500 0.000000 0.034500
        rotation 0.000000 -0.000000 -1.000000 1.570800
        children [
          Shape {
            appearance DEF part_2_material PBRAppearance {
              baseColor 0.2 0.2 0.2
              roughness 1.000000
              metalness 0
            }
            geometry DEF part_2 Mesh {
              url "robotarm_assets/part_2.stl"
            }
            castShadows FALSE
          }
        ]
      }
      Pose {
        translation 0.015500 -0.000200 0.034500
        rotation 0.000000 -0.000000 -1.000000 1.570800
        children [
          Shape {
            appearance DEF dummy_dc13_idle_material PBRAppearance {
              baseColor 0.2 0.2 0.2
              roughness 1.000000
              metalness 0
            }
            geometry DEF dummy_dc13_idle Mesh {
              url "robotarm_assets/dummy_dc13_idle.stl"
            }
            castShadows FALSE
          }
        ]
      }
      HingeJoint {
        jointParameters HingeJointParameters {
          axis 0.000003 -0.000000 -1.000000
          anchor 0.015500 -0.000200 0.059000
        }
        device [
          RotationalMotor {
            name "joint_1"
            maxVelocity 10.0
            minPosition -3.1415
            maxPosition 3.1415
            maxTorque 10.8
          }
          PositionSensor {
            name "joint_1_sensor"
          }
        ]
        endPoint Solid {
          translation 0.015500 -0.000200 0.059000
          rotation -0.707105 0.707108 -0.000001 3.141591
          children [
            Pose {
              translation 0.000000 0.000000 0.024500
              rotation -1.000000 -0.000000 0.000000 3.141590
              children [
                Shape {
                  appearance DEF part_3_material PBRAppearance {
                    baseColor 0.2 0.2 0.2
                    roughness 1.000000
                    metalness 0
                  }
                  geometry DEF part_3 Mesh {
                    url "robotarm_assets/part_3.stl"
                  }
                }
              ]
            }
            Pose {
              translation -0.000000 0.000200 0.024500
              rotation -1.000000 -0.000000 0.000000 3.141590
              children [
                Shape {
                  appearance DEF dummy_dc13_idle_2_material PBRAppearance {
                    baseColor 0.2 0.2 0.2
                    roughness 1.000000
                    metalness 0
                  }
                  geometry DEF dummy_dc13_idle__2 Mesh {
                    url "robotarm_assets/dummy_dc13_idle__2.stl"
                  }
                  castShadows FALSE
                }
              ]
            }
            HingeJoint {
              jointParameters HingeJointParameters {
                axis -1.000000 -0.000000 -0.000004
                anchor 0.024500 0.000200 -0.045828
              }
              device [
                RotationalMotor {
                  name "joint_2"
                  maxVelocity 10.0
                  minPosition -2.00713
                  maxPosition 0
                  maxTorque 10.8
                }
                PositionSensor {
                  name "joint_2_sensor"
                }
              ]
              endPoint Solid {
                translation 0.024500 0.000200 -0.045828
                rotation 0.000000 -1.000000 0.000000 1.570800
                children [
                  Pose {
                    translation -0.000022 -0.131500 0.024544
                    rotation -0.577350 0.577350 0.577352 2.094399
                    children [
                      Shape {
                        appearance DEF fr12_s102_k_material PBRAppearance {
                          baseColor 0.2 0.2 0.2
                          roughness 1.000000
                          metalness 0
                        }
                        geometry DEF fr12_s102_k Mesh {
                          url "robotarm_assets/fr12_s102_k.stl"
                        }
                      }
                    ]
                  }
                  Pose {
                    translation -0.000022 -0.152500 0.004544
                    rotation 1.000000 0.000000 0.000000 3.141590
                    children [
                      Shape {
                        appearance DEF dummy_dc12_material PBRAppearance {
                          baseColor 0.2 0.2 0.2
                          roughness 1.000000
                          metalness 0
                        }
                        geometry DEF dummy_dc12 Mesh {
                          url "robotarm_assets/dummy_dc12.stl"
                        }
                        castShadows FALSE
                      }
                    ]
                  }
                  Pose {
                    translation -0.000022 -0.140000 0.024544
                    rotation -0.000000 1.000000 0.000000 1.570800
                    children [
                      Shape {
                        appearance DEF part_2_2_material PBRAppearance {
                          baseColor 0.2 0.2 0.2
                          roughness 1.000000
                          metalness 0
                        }
                        geometry DEF part_2__2 Mesh {
                          url "robotarm_assets/part_2__2.stl"
                        }
                      }
                    ]
                  }
                  Pose {
                    translation 0.000000 -0.000000 0.024500
                    rotation 0.707105 0.000001 -0.707108 3.141591
                    children [
                      Shape {
                        appearance DEF fr13_h101_k_material PBRAppearance {
                          baseColor 0.2 0.2 0.2
                          roughness 1.000000
                          metalness 0
                        }
                        geometry DEF fr13_h101_k Mesh {
                          url "robotarm_assets/fr13_h101_k.stl"
                        }
                      }
                    ]
                  }
                  HingeJoint {
                    jointParameters HingeJointParameters {
                      axis 0.000000 0.000000 1.000000
                      anchor -0.000022 -0.152500 0.005544
                    }
                    device [
                      RotationalMotor {
                        name "joint_3"
                        maxVelocity 10.0
                        minPosition -1.5708
                        maxPosition 2.0944
                        maxTorque 10.0
                      }
                      PositionSensor {
                        name "joint_3_sensor"
                      }
                    ]
                    endPoint Solid {
                      translation -0.000022 -0.152500 0.005544
                      children [
                        Pose {
                          translation -0.000000 -0.102500 0.019000
                          rotation -0.577350 0.577350 0.577352 2.094399
                          children [
                            Shape {
                              appearance DEF part_2_3_material PBRAppearance {
                                baseColor 0.2 0.2 0.2
                                roughness 1.000000
                                metalness 0
                              }
                              geometry DEF part_2__3 Mesh {
                                url "robotarm_assets/part_2__3.stl"
                              }
                            }
                          ]
                        }
                        Pose {
                          translation -0.000000 -0.123500 -0.001000
                          rotation -1.000000 -0.000000 0.000000 3.141590
                          children [
                            Shape {
                              castShadows FALSE
                              appearance DEF dummy_dc12_2_material PBRAppearance {
                                baseColor 0.2 0.2 0.2
                                roughness 1.000000
                                metalness 0
                              }
                              geometry USE dummy_dc12
                            }
                          ]
                        }
                        Pose {
                          translation -0.000000 -0.000000 0.019000
                          rotation 0.707105 0.000001 -0.707108 3.141591
                          children [
                            Shape {
                              appearance DEF fr12_h101_k_material PBRAppearance {
                                baseColor 0.2 0.2 0.2
                                roughness 1.000000
                                metalness 0
                              }
                              geometry DEF fr12_h101_k Mesh {
                                url "robotarm_assets/fr12_h101_k.stl"
                              }
                            }
                          ]
                        }
                        Pose {
                          translation -0.000000 -0.102500 0.019000
                          rotation -0.577350 0.577350 0.577352 2.094399
                          children [
                            Shape {
                              appearance DEF fr12_s102_k_2_material PBRAppearance {
                                baseColor 0.2 0.2 0.2
                                roughness 1.000000
                                metalness 0
                              }
                              geometry USE fr12_s102_k
                            }
                          ]
                        }
                        HingeJoint {
                          jointParameters HingeJointParameters {
                            axis 0.000000 0.000000 1.000000
                            anchor -0.000000 -0.123500 -0.000000
                          }
                          device [
                            RotationalMotor {
                              name "joint_4"
                              maxVelocity 10.0
                              minPosition -1.5708
                              maxPosition 1.74533
                              maxTorque 10.0
                            }
                            PositionSensor {
                              name "joint_4_sensor"
                            }
                          ]
                          endPoint Solid {
                            translation -0.000000 -0.123500 -0.000000
                            children [
                              Pose {
                                translation -0.008500 -0.062650 0.019075
                                rotation -0.577350 -0.577350 -0.577352 2.094399
                                children [
                                  Shape {
                                    appearance DEF j4_j5_mirrored_material PBRAppearance {
                                      baseColor 0.2 0.2 0.2
                                      roughness 1.000000
                                      metalness 0
                                    }
                                    geometry DEF j4_j5_mirrored Mesh {
                                      url "robotarm_assets/j4_j5_mirrored.stl"
                                    }
                                  }
                                ]
                              }
                              Pose {
                                translation -0.008500 -0.062650 0.019075
                                rotation -0.577350 -0.577350 -0.577352 2.094399
                                children [
                                  Shape {
                                    appearance DEF j4_j5_mirrored_2_material PBRAppearance {
                                      baseColor 0.2 0.2 0.2
                                      roughness 1.000000
                                      metalness 0
                                    }
                                    geometry DEF j4_j5_mirrored__2 Mesh {
                                      url "robotarm_assets/j4_j5_mirrored__2.stl"
                                    }
                                  }
                                ]
                              }
                              Pose {
                                translation -0.008500 -0.062650 0.019075
                                rotation 0.577350 0.577350 -0.577352 2.094399
                                children [
                                  Shape {
                                    appearance DEF dummy_dc12_3_material PBRAppearance {
                                      baseColor 0.2 0.2 0.2
                                      roughness 1.000000
                                      metalness 0
                                    }
                                    geometry DEF dummy_dc12__2 Mesh {
                                      url "robotarm_assets/dummy_dc12__2.stl"
                                    }
                                    castShadows FALSE
                                  }
                                ]
                              }
                              HingeJoint {
                                jointParameters HingeJointParameters {
                                  axis -0.000004 1.000000 0.000000
                                  anchor 0.000000 -0.061650 0.019075
                                }
                                device [
                                  RotationalMotor {
                                    name "joint_5"
                                    maxVelocity 10.0
                                    minPosition -1.5708
                                    maxPosition 1.5708
                                    maxTorque 10.0
                                  }
                                  PositionSensor {
                                    name "joint_5_sensor"
                                  }
                                ]
                                endPoint Solid {
                                  translation 0.000000 -0.061650 0.019075
                                  rotation -0.577350 0.577350 0.577352 2.094399
                                  children [
                                    Pose {
                                      rotation 1.000000 -0.000000 -0.000000 3.141590
                                      children [
                                        Shape {
                                          appearance DEF p01_05_base_material PBRAppearance {
                                            baseColor 0.2 0.2 0.2
                                            roughness 1.000000
                                            metalness 0
                                          }
                                          geometry DEF p01_05_base Mesh {
                                            url "robotarm_assets/p01_05_base.stl"
                                          }
                                          castShadows FALSE
                                        }
                                      ]
                                    }
                                    Pose {
                                      translation 0.000000 0.000050 -0.000000
                                      rotation 1.000000 -0.000000 -0.000000 3.141590
                                      children [
                                        Shape {
                                          appearance DEF p01_07_body_material PBRAppearance {
                                            baseColor 0.4 0.05 0.05
                                            roughness 1.000000
                                            metalness 0
                                          }
                                          geometry DEF p01_07_body Mesh {
                                            url "robotarm_assets/p01_07_body.stl"
                                          }
                                        }
                                      ]
                                    }
                                    Pose {
                                      translation -0.000000 -0.000050 0.000000
                                      rotation -1.000000 0.000000 -0.000000 3.141590
                                      children [
                                        Shape {
                                          appearance DEF p01_06_body_motor_material PBRAppearance {
                                            baseColor 0.4 0.05 0.05
                                            roughness 1.000000
                                            metalness 0
                                          }
                                          geometry DEF p01_06_body_motor Mesh {
                                            url "robotarm_assets/p01_06_body_motor.stl"
                                          }
                                        }
                                      ]
                                    }
                                    Pose {
                                      translation 0.027500 0.022800 -0.092650
                                      rotation -0.707105 0.707108 -0.000001 3.141591
                                      children [
                                        Shape {
                                          appearance DEF dummy_dc12_4_material PBRAppearance {
                                            baseColor 0.2 0.2 0.2
                                            roughness 1.000000
                                            metalness 0
                                          }
                                          geometry DEF dummy_dc12__3 Mesh {
                                            url "robotarm_assets/dummy_dc12__3.stl"
                                          }
                                          castShadows FALSE
                                        }
                                      ]
                                    }
                                    HingeJoint {
                                      jointParameters HingeJointParameters {
                                        axis -0.000004 -1.000000 0.000000
                                        anchor 0.019000 -0.003950 -0.030000
                                      }
                                      device [
                                        RotationalMotor {
                                          name "joint_6"
                                          maxVelocity 10.0
                                          minPosition -1.39626
                                          maxPosition 0.0001
                                          maxTorque 10.0
                                        }
                                        PositionSensor {
                                          name "joint_6_sensor"
                                        }
                                      ]
                                      endPoint Solid {
                                        translation 0.019000 -0.003950 -0.030000
                                        rotation 0.577350 0.577350 -0.577352 2.094399
                                        children [
                                          Pose {
                                            translation 0.019000 -0.030000 -0.003850
                                            rotation 0.000001 -0.707108 -0.707105 3.141591
                                            children [
                                              Shape {
                                                appearance DEF p01_01_gearlink_motor_material PBRAppearance {
                                                  baseColor 0.4 0.05 0.05
                                                  roughness 1.000000
                                                  metalness 0
                                                }
                                                geometry DEF p01_01_gearlink_motor Mesh {
                                                  url "robotarm_assets/p01_01_gearlink_motor.stl"
                                                }
                                              }
                                            ]
                                          }
                                        ]
                                        name "link6"
                                        boundingObject Pose {
                                          translation 0.019000 -0.030000 -0.003850
                                          rotation 0.000001 -0.707108 -0.707105 3.141591
                                          children [
                                            USE p01_01_gearlink_motor
                                          ]
                                        }
                                        physics Physics {
                                          density -1
                                          mass 0.006597
                                          centerOfMass [ 0.001481 0.013111 -0.004460 ]
                                          inertiaMatrix [
                                            2.745000e-06 2.493600e-07 2.909280e-06
                                            1.876170e-07 -5.675000e-09 -5.718400e-08
                                          ]
                                        }
                                      }
                                    }
                                    HingeJoint {
                                      jointParameters HingeJointParameters {
                                        axis -0.000004 1.000000 0.000000
                                        anchor -0.019000 0.003950 -0.030000
                                      }
                                      device [
                                        RotationalMotor {
                                          name "joint_6_mimic_gear"
                                          multiplier 1
                                          maxVelocity 10.0
                                          minPosition -3.141592653589793
                                          maxPosition 3.141592653589793
                                          maxTorque 10.0
                                        }
                                        PositionSensor {
                                          name "joint_6_mimic_gear_sensor"
                                        }
                                      ]
                                      endPoint Solid {
                                        translation -0.019000 0.003950 -0.030000
                                        rotation -0.577350 0.577350 0.577352 2.094399
                                        children [
                                          Pose {
                                            translation 0.019000 -0.030000 -0.003850
                                            rotation -1.000000 0.000000 -0.000000 1.570800
                                            children [
                                              Shape {
                                                appearance DEF p01_02_gearlink_material PBRAppearance {
                                                  baseColor 0.4 0.05 0.05
                                                  roughness 1.000000
                                                  metalness 0
                                                }
                                                geometry DEF p01_02_gearlink Mesh {
                                                  url "robotarm_assets/p01_02_gearlink.stl"
                                                }
                                              }
                                            ]
                                          }
                                        ]
                                        name "link7"
                                        boundingObject Pose {
                                          translation 0.019000 -0.030000 -0.003850
                                          rotation -1.000000 0.000000 -0.000000 1.570800
                                          children [
                                            USE p01_02_gearlink
                                          ]
                                        }
                                        physics Physics {
                                          density -1
                                          mass 0.006402
                                          centerOfMass [ 0.001579 0.013572 -0.003884 ]
                                          inertiaMatrix [
                                            2.685580e-06 2.305420e-07 2.867350e-06
                                            1.897310e-07 -3.440000e-10 -3.050000e-10
                                          ]
                                        }
                                      }
                                    }
                                    HingeJoint {
                                      jointParameters HingeJointParameters {
                                        axis -0.000004 -1.000000 0.000000
                                        anchor 0.012500 -0.003950 -0.055174
                                      }
                                      device [
                                        RotationalMotor {
                                          name "joint_6_mimic_L1"
                                          maxVelocity 10.0
                                          minPosition -3.141592653589793
                                          maxPosition 3.141592653589793
                                          maxTorque 10.0
                                        }
                                        PositionSensor {
                                          name "joint_6_mimic_L1_sensor"
                                        }
                                      ]
                                      endPoint Solid {
                                        translation 0.012500 -0.003950 -0.055174
                                        rotation 0.577350 0.577350 -0.577352 2.094399
                                        children [
                                          Pose {
                                            translation -0.012500 0.105174 -0.003850
                                            rotation 1.000000 0.000000 0.000000 1.570800
                                            children [
                                              Shape {
                                                appearance DEF p01_03_link_material PBRAppearance {
                                                  baseColor 0.4 0.05 0.05
                                                  roughness 1.000000
                                                  metalness 0
                                                }
                                                geometry DEF p01_03_link Mesh {
                                                  url "robotarm_assets/p01_03_link.stl"
                                                }
                                              }
                                            ]
                                          }
                                          HingeJoint {
                                            jointParameters HingeJointParameters {
                                              axis 0.000000 -0.000003 -1.000000
                                              anchor 0.000000 0.050000 0.000000
                                            }
                                            device [
                                              RotationalMotor {
                                                name "joint_6_mimic_L3"
                                                maxVelocity 10.0
                                                minPosition -3.141592653589793
                                                maxPosition 3.141592653589793
                                                maxTorque 10.0
                                              }
                                              PositionSensor {
                                                name "joint_6_mimic_L3_sensor"
                                              }
                                            ]
                                            endPoint Solid {
                                              translation 0.000000 0.050000 0.000000
                                              rotation 1.000000 0.000000 0.000000 3.141590
                                              children [
                                                Pose {
                                                  translation -0.104415 0.021182 0.004000
                                                  rotation -0.577350 0.577352 -0.577350 2.094399
                                                  children [
                                                    Shape {
                                                      appearance DEF p01_04_finger_material PBRAppearance {
                                                        baseColor 0.4 0.05 0.05
                                                        roughness 1.000000
                                                        metalness 0
                                                      }
                                                      geometry DEF p01_04_finger Mesh {
                                                        url "robotarm_assets/p01_04_finger.stl"
                                                      }
                                                    }
                                                  ]
                                                }
                                                HingeJoint {
                                                  jointParameters HingeJointParameters {
                                                    axis 0.000000 -0.000003 -1.000000
                                                    anchor -0.025174 -0.006500 0.000000
                                                  }
                                                  device [
                                                    RotationalMotor {
                                                      name "joint_6_mimic_L2"
                                                      maxVelocity 10.0
                                                      minPosition -3.141592653589793
                                                      maxPosition 3.141592653589793
                                                      maxTorque 10.0
                                                    }
                                                    PositionSensor {
                                                      name "joint_6_mimic_L2_sensor"
                                                    }
                                                  ]
                                                  endPoint Solid {
                                                    translation -0.025174 -0.006500 0.000000
                                                    rotation 1.000000 0.000000 0.000000 3.141590
                                                    children [
                                                      Pose {
                                                        translation 0.019000 -0.080000 -0.003850
                                                        rotation 0.000001 -0.707108 -0.707105 3.141591
                                                        children [
                                                          Shape {
                                                            appearance DEF p01_01_gearlink_motor_2_material PBRAppearance {
                                                              baseColor 0.4 0.05 0.05
                                                              roughness 1.000000
                                                              metalness 0
                                                            }
                                                            geometry USE p01_01_gearlink_motor
                                                          }
                                                        ]
                                                      }
                                                    ]
                                                    name "link6_2"
                                                    boundingObject Pose {
                                                      translation 0.019000 -0.080000 -0.003850
                                                      rotation 0.000001 -0.707108 -0.707105 3.141591
                                                      children [
                                                        USE p01_01_gearlink_motor
                                                      ]
                                                    }
                                                    physics Physics {
                                                      density -1
                                                      mass 0.006597
                                                      centerOfMass [ 0.001481 -0.036889 -0.004460 ]
                                                      inertiaMatrix [
                                                        2.745000e-06 2.493600e-07 2.909280e-06
                                                        1.876170e-07 -5.675000e-09 -5.718400e-08
                                                      ]
                                                    }
                                                  }
                                                }
                                              ]
                                              name "link10"
                                              boundingObject Pose {
                                                translation -0.104415 0.021182 0.004000
                                                rotation -0.577350 0.577352 -0.577350 2.094399
                                                children [
                                                  USE p01_04_finger
                                                ]
                                              }
                                              physics Physics {
                                                density -1
                                                mass 0.016561
                                                centerOfMass [ 0.018475 0.008665 0.004000 ]
                                                inertiaMatrix [
                                                  1.623620e-06 7.986550e-06 8.887000e-06
                                                  -2.359140e-06 -0.000000e+00 -0.000000e+00
                                                ]
                                              }
                                            }
                                          }
                                        ]
                                        name "link9"
                                        boundingObject Pose {
                                          translation -0.012500 0.105174 -0.003850
                                          rotation 1.000000 0.000000 0.000000 1.570800
                                          children [
                                            USE p01_03_link
                                          ]
                                        }
                                        physics Physics {
                                          density -1
                                          mass 0.1
                                          centerOfMass [ -0.000000 0.025000 -0.003850 ]
                                          # inertiaMatrix [
                                          #   1.099250e-06 5.454900e-08 1.113420e-06
                                          #   0.000000e+00 -0.000000e+00 0.000000e+00
                                          # ]
                                        }
                                      }
                                    }
                                    HingeJoint {
                                      jointParameters HingeJointParameters {
                                        axis -0.000004 -1.000000 0.000000
                                        anchor -0.012500 0.003950 -0.055174
                                      }
                                      device [
                                        RotationalMotor {
                                          name "joint_6_mimic_R1"
                                          multiplier -1
                                          maxVelocity 10.0
                                          minPosition -3.141592653589793
                                          maxPosition 3.141592653589793
                                          maxTorque 10.0
                                        }
                                        PositionSensor {
                                          name "joint_6_mimic_R1_sensor"
                                        }
                                      ]
                                      endPoint Solid {
                                        translation -0.012500 0.003950 -0.055174
                                        rotation 0.577350 0.577350 -0.577352 2.094399
                                        children [
                                          Pose {
                                            translation 0.012500 -0.105174 0.003850
                                            rotation 0.000001 -0.707108 -0.707105 3.141591
                                            children [
                                              Shape {
                                                appearance DEF p01_03_link_2_material PBRAppearance {
                                                  baseColor 0.4 0.05 0.05
                                                  roughness 1.000000
                                                  metalness 0
                                                }
                                                geometry USE p01_03_link
                                              }
                                            ]
                                          }
                                          HingeJoint {
                                            jointParameters HingeJointParameters {
                                              axis 0.000000 0.000003 -1.000000
                                              anchor 0.000000 -0.050000 -0.000000
                                            }
                                            device [
                                              RotationalMotor {
                                                name "joint_6_mimic_R3"
                                                multiplier -1
                                                maxVelocity 10.0
                                                minPosition -3.141592653589793
                                                maxPosition 3.141592653589793
                                                maxTorque 10.0
                                              }
                                              PositionSensor {
                                                name "joint_6_mimic_R3_sensor"
                                              }
                                            ]
                                            endPoint Solid {
                                              translation 0.000000 -0.050000 -0.000000
                                              rotation -1.000000 -0.000000 0.000000 3.141590
                                              children [
                                                Pose {
                                                  translation -0.104415 -0.021182 -0.004000
                                                  rotation 0.577350 0.577352 0.577350 2.094399
                                                  children [
                                                    Shape {
                                                      appearance DEF p01_04_finger_2_material PBRAppearance {
                                                        baseColor 0.4 0.05 0.05
                                                        roughness 1.000000
                                                        metalness 0
                                                      }
                                                      geometry USE p01_04_finger
                                                    }
                                                  ]
                                                }
                                                HingeJoint {
                                                  jointParameters HingeJointParameters {
                                                    axis 0.000000 0.000000 1.000000
                                                    anchor -0.025174 0.006500 0.000000
                                                  }
                                                  device [
                                                    RotationalMotor {
                                                      name "joint_6_mimic_R2"
                                                      multiplier 1
                                                      maxVelocity 10.0
                                                      minPosition -3.141592653589793
                                                      maxPosition 3.141592653589793
                                                      maxTorque 10.0
                                                    }
                                                    PositionSensor {
                                                      name "joint_6_mimic_R2_sensor"
                                                    }
                                                  ]
                                                  endPoint Solid {
                                                    translation -0.025174 0.006500 0.000000
                                                    children [
                                                      Pose {
                                                        translation 0.019000 -0.080000 -0.003850
                                                        rotation -1.000000 0.000000 0.000000 1.570800
                                                        children [
                                                          Shape {
                                                            appearance DEF p01_02_gearlink_2_material PBRAppearance {
                                                              baseColor 0.4 0.05 0.05
                                                              roughness 1.000000
                                                              metalness 0
                                                            }
                                                            geometry USE p01_02_gearlink
                                                          }
                                                        ]
                                                      }
                                                    ]
                                                    name "link7_2"
                                                    boundingObject Pose {
                                                      translation 0.019000 -0.080000 -0.003850
                                                      rotation -1.000000 0.000000 0.000000 1.570800
                                                      children [
                                                        USE p01_02_gearlink
                                                      ]
                                                    }
                                                    physics Physics {
                                                      density -1
                                                      mass 0.006402
                                                      centerOfMass [ 0.001579 -0.036428 -0.003884 ]
                                                      inertiaMatrix [
                                                        2.685580e-06 2.305420e-07 2.867350e-06
                                                        1.897310e-07 -3.440000e-10 -3.050000e-10
                                                      ]
                                                    }
                                                  }
                                                }
                                              ]
                                              name "link11"
                                              boundingObject Pose {
                                                translation -0.104415 -0.021182 -0.004000
                                                rotation 0.577350 0.577352 0.577350 2.094399
                                                children [
                                                  USE p01_04_finger
                                                ]
                                              }
                                              physics Physics {
                                                density -1
                                                mass 0.016561
                                                centerOfMass [ 0.018475 -0.008665 -0.004000 ]
                                                inertiaMatrix [
                                                  1.623620e-06 7.986550e-06 8.887000e-06
                                                  2.359140e-06 0.000000e+00 -0.000000e+00
                                                ]
                                              }
                                            }
                                          }
                                        ]
                                        name "link8"
                                        boundingObject Pose {
                                          translation 0.012500 -0.105174 0.003850
                                          rotation 0.000001 -0.707108 -0.707105 3.141591
                                          children [
                                            USE p01_03_link
                                          ]
                                        }
                                        physics Physics {
                                          density -1
                                          mass 0.1
                                          centerOfMass [ 0.000000 -0.025000 0.003850 ]
                                          # inertiaMatrix [
                                          #   1.099250e-06 5.454900e-08 1.113420e-06
                                          #   0.000000e+00 -0.000000e+00 -0.000000e+00
                                          # ]
                                        }
                                      }
                                    }
                                  ]
                                  name "link5"
                                  boundingObject Group {
                                    children [
                                      Pose {
                                        rotation 1.000000 -0.000000 -0.000000 3.141590
                                        children [
                                          USE p01_05_base
                                        ]
                                      }
                                      Pose {
                                        translation 0.000000 0.000050 -0.000000
                                        rotation 1.000000 -0.000000 -0.000000 3.141590
                                        children [
                                          USE p01_07_body
                                        ]
                                      }
                                      Pose {
                                        translation -0.000000 -0.000050 0.000000
                                        rotation -1.000000 0.000000 -0.000000 3.141590
                                        children [
                                          USE p01_06_body_motor
                                        ]
                                      }
                                      Pose {
                                        translation 0.027500 0.022800 -0.092650
                                        rotation -0.707105 0.707108 -0.000001 3.141591
                                        children [
                                          USE dummy_dc12__3
                                        ]
                                      }
                                    ]
                                  }
                                  physics Physics {
                                    density -1
                                    mass 0.029448
                                    centerOfMass [ -0.000777 -0.000308 -0.029745 ]
                                    inertiaMatrix [
                                      9.746410e-06 1.540880e-05 8.033260e-06
                                      1.911040e-07 -5.836000e-09 -2.313000e-09
                                    ]
                                  }
                                }
                              }
                            ]
                            name "link4"
                            boundingObject Group {
                              children [
                                Pose {
                                  translation -0.008500 -0.062650 0.019075
                                  rotation -0.577350 -0.577350 -0.577352 2.094399
                                  children [
                                    USE j4_j5_mirrored
                                  ]
                                }
                                Pose {
                                  translation -0.008500 -0.062650 0.019075
                                  rotation -0.577350 -0.577350 -0.577352 2.094399
                                  children [
                                    USE j4_j5_mirrored__2
                                  ]
                                }
                                Pose {
                                  translation -0.008500 -0.062650 0.019075
                                  rotation 0.577350 0.577350 -0.577352 2.094399
                                  children [
                                    USE dummy_dc12__2
                                  ]
                                }
                              ]
                            }
                            physics Physics {
                              density -1
                              mass 0.2
                              centerOfMass [ 0.000000 0.000000 0.000000 ]
                              inertiaMatrix [
                                1.000000e-09 1.000000e-09 1.000000e-09
                                0.000000e+00 0.000000e+00 0.000000e+00
                              ]
                            }
                          }
                        }
                      ]
                      name "link3"
                      boundingObject Group {
                        children [
                          Pose {
                            translation -0.000000 -0.102500 0.019000
                            rotation -0.577350 0.577350 0.577352 2.094399
                            children [
                              USE part_2__3
                            ]
                          }
                          Pose {
                            translation -0.000000 -0.123500 -0.001000
                            rotation -1.000000 -0.000000 0.000000 3.141590
                            children [
                              USE dummy_dc12
                            ]
                          }
                          Pose {
                            translation -0.000000 -0.000000 0.019000
                            rotation 0.707105 0.000001 -0.707108 3.141591
                            children [
                              USE fr12_h101_k
                            ]
                          }
                          Pose {
                            translation -0.000000 -0.102500 0.019000
                            rotation -0.577350 0.577350 0.577352 2.094399
                            children [
                              USE fr12_s102_k
                            ]
                          }
                        ]
                      }
                      physics Physics {
                        density -1
                        mass 0.108493
                        centerOfMass [ 0.000000 -0.097142 0.018572 ]
                        inertiaMatrix [
                          1.189450e-04 1.799720e-05 1.136340e-04
                          -0.000000e+00 -0.000000e+00 -6.838030e-07
                        ]
                      }
                    }
                  }
                ]
                name "link2"
                boundingObject Group {
                  children [
                    Pose {
                      translation -0.000022 -0.131500 0.024544
                      rotation -0.577350 0.577350 0.577352 2.094399
                      children [
                        USE fr12_s102_k
                      ]
                    }
                    Pose {
                      translation -0.000022 -0.152500 0.004544
                      rotation 1.000000 0.000000 0.000000 3.141590
                      children [
                        USE dummy_dc12
                      ]
                    }
                    Pose {
                      translation -0.000022 -0.140000 0.024544
                      rotation -0.000000 1.000000 0.000000 1.570800
                      children [
                        USE part_2__2
                      ]
                    }
                    Pose {
                      translation 0.000000 -0.000000 0.024500
                      rotation 0.707105 0.000001 -0.707108 3.141591
                      children [
                        USE fr13_h101_k
                      ]
                    }
                  ]
                }
                physics Physics {
                  density -1
                  mass 0.122875
                  centerOfMass [ -0.000019 -0.113233 0.024159 ]
                  inertiaMatrix [
                    2.756600e-04 2.449380e-05 2.664760e-04
                    -3.711800e-08 6.540000e-10 -1.210330e-06
                  ]
                }
              }
            }
          ]
          name "link1"
          boundingObject Group {
            children [
              Pose {
                translation 0.000000 0.000000 0.024500
                rotation -1.000000 -0.000000 0.000000 3.141590
                children [
                  USE part_3
                ]
              }
              Pose {
                translation -0.000000 0.000200 0.024500
                rotation -1.000000 -0.000000 0.000000 3.141590
                children [
                  USE dummy_dc13_idle__2
                ]
              }
            ]
          }
          physics Physics {
            density -1
            mass 0.244315
            centerOfMass [ 0.000461 0.020735 -0.039510 ]
            inertiaMatrix [
              1.475260e-04 1.173840e-04 1.367750e-04
              9.353420e-07 7.111440e-07 -2.614530e-06
            ]
          }
        }
      }
    ]
    name IS name
    boundingObject Group {
      children [
        Pose {
          translation 0.015500 0.000000 0.034500
          rotation 0.000000 -0.000000 -1.000000 1.570800
          children [
            # USE part_2
            Box { size 0.1 0.1 0.05 }
          ]
        }
        Pose {
          translation 0.015500 -0.000200 0.034500
          rotation 0.000000 -0.000000 -1.000000 1.570800
          children [
            # USE dummy_dc13_idle
          ]
        }
      ]
    }
    # physics Physics {
    #   density -1
    #   mass 0.289487
    #   centerOfMass [ 0.000310 -0.000114 0.025060 ]
    #   inertiaMatrix [
    #     1.473780e-04 1.987100e-04 1.880000e-04
    #     5.315000e-09 -1.085700e-06 3.340250e-07
    #   ]
    # }
  }
}
