<?xml version="1.0" ?>
<robot name="my_robot">
  <link name="link0">
    <inertial>
      <origin xyz="-0.000309241 1.065e-09 0.0263888" rpy="0 0 0"/>
      <mass value="0.264096"/>
      <inertia ixx="0.000113185" ixy="-3e-12" ixz="1.00015e-06" iyy="0.000175727" iyz="8e-12" izz="0.000147128"/>
    </inertial>
    <visual>
      <origin xyz="-0.0155 -0 0.0345" rpy="0 -0 1.5708"/>
      <geometry>
        <mesh filename="assets/dummy_dc13_idle.stl"/>
      </geometry>
      <material name="dummy_dc13_idle_material">
        <color rgba="0.980392 0.713725 0.00392157 1"/>
      </material>
    </visual>
    <collision>
      <origin xyz="-0.0155 -0 0.0345" rpy="0 -0 1.5708"/>
      <geometry>
        <mesh filename="assets/dummy_dc13_idle.stl"/>
      </geometry>
    </collision>
    <visual>
      <origin xyz="-0.0155 0 0.0345" rpy="0 -0 1.5708"/>
      <geometry>
        <mesh filename="assets/part_2.stl"/>
      </geometry>
      <material name="part_2_material">
        <color rgba="0.615686 0.811765 0.929412 1"/>
      </material>
    </visual>
    <collision>
      <origin xyz="-0.0155 0 0.0345" rpy="0 -0 1.5708"/>
      <geometry>
        <mesh filename="assets/part_2.stl"/>
      </geometry>
    </collision>
  </link>
  <link name="link1">
    <inertial>
      <origin xyz="-0.0186967 -0.000784302 -0.0430186" rpy="0 0 0"/>
      <mass value="0.212381"/>
      <inertia ixx="8.79949e-05" ixy="-2.86541e-06" ixz="-8.1322e-06" iyy="0.000118099" iyz="-2.55396e-07" izz="0.000120043"/>
    </inertial>
    <visual>
      <origin xyz="0 -0 0.0245" rpy="-3.14159 -0 1.64104"/>
      <geometry>
        <mesh filename="assets/part_3.stl"/>
      </geometry>
      <material name="part_3_material">
        <color rgba="0.647059 0.647059 0.647059 1"/>
      </material>
    </visual>
    <collision>
      <origin xyz="0 -0 0.0245" rpy="-3.14159 -0 1.64104"/>
      <geometry>
        <mesh filename="assets/part_3.stl"/>
      </geometry>
    </collision>
    <visual>
      <origin xyz="0 -0 0.0245" rpy="-3.14159 -0 1.64104"/>
      <geometry>
        <mesh filename="assets/dummy_dc13_idle__2.stl"/>
      </geometry>
      <material name="dummy_dc13_idle_2_material">
        <color rgba="0.231373 0.380392 0.705882 1"/>
      </material>
    </visual>
    <collision>
      <origin xyz="0 -0 0.0245" rpy="-3.14159 -0 1.64104"/>
      <geometry>
        <mesh filename="assets/dummy_dc13_idle__2.stl"/>
      </geometry>
    </collision>
  </link>
  <link name="link2">
    <inertial>
      <origin xyz="0.0242489 -0.110606 0.0241592" rpy="0 0 0"/>
      <mass value="0.122875"/>
      <inertia ixx="0.000264139" ixy="5.25439e-05" ixz="2.60031e-07" iyy="3.60144e-05" iyz="-1.18207e-06" izz="0.000266476"/>
    </inertial>
    <visual>
      <origin xyz="0.0281605 -0.128449 0.024544" rpy="-1.78679 1.5708 0"/>
      <geometry>
        <mesh filename="assets/fr12_s102_k.stl"/>
      </geometry>
      <material name="fr12_s102_k_material">
        <color rgba="0.647059 0.647059 0.647059 1"/>
      </material>
    </visual>
    <collision>
      <origin xyz="0.0281605 -0.128449 0.024544" rpy="-1.78679 1.5708 0"/>
      <geometry>
        <mesh filename="assets/fr12_s102_k.stl"/>
      </geometry>
    </collision>
    <visual>
      <origin xyz="0.0326611 -0.148961 0.004544" rpy="-3.14159 -0 0.215989"/>
      <geometry>
        <mesh filename="assets/dummy_dc12.stl"/>
      </geometry>
      <material name="dummy_dc12_material">
        <color rgba="0.917647 0.917647 0.917647 1"/>
      </material>
    </visual>
    <collision>
      <origin xyz="0.0326611 -0.148961 0.004544" rpy="-3.14159 -0 0.215989"/>
      <geometry>
        <mesh filename="assets/dummy_dc12.stl"/>
      </geometry>
    </collision>
    <visual>
      <origin xyz="0.0299821 -0.136752 0.024544" rpy="-0.215989 1.5708 0"/>
      <geometry>
        <mesh filename="assets/part_2__2.stl"/>
      </geometry>
      <material name="part_2_2_material">
        <color rgba="0.615686 0.811765 0.929412 1"/>
      </material>
    </visual>
    <collision>
      <origin xyz="0.0299821 -0.136752 0.024544" rpy="-0.215989 1.5708 0"/>
      <geometry>
        <mesh filename="assets/part_2__2.stl"/>
      </geometry>
    </collision>
    <visual>
      <origin xyz="0 -0 0.0245" rpy="2.9256 1.5708 0"/>
      <geometry>
        <mesh filename="assets/fr13_h101_k.stl"/>
      </geometry>
      <material name="fr13_h101_k_material">
        <color rgba="0.768627 0.886275 0.952941 1"/>
      </material>
    </visual>
    <collision>
      <origin xyz="0 -0 0.0245" rpy="2.9256 1.5708 0"/>
      <geometry>
        <mesh filename="assets/fr13_h101_k.stl"/>
      </geometry>
    </collision>
  </link>
  <link name="link3">
    <inertial>
      <origin xyz="0.0971416 0 0.0185718" rpy="0 0 0"/>
      <mass value="0.108493"/>
      <inertia ixx="1.79972e-05" ixy="0" ixz="6.83803e-07" iyy="0.000118945" iyz="-0" izz="0.000113634"/>
    </inertial>
    <visual>
      <origin xyz="0.1025 0 0.019" rpy="3.14159 1.5708 0"/>
      <geometry>
        <mesh filename="assets/part_2__3.stl"/>
      </geometry>
      <material name="part_2_3_material">
        <color rgba="0.917647 0.917647 0.917647 1"/>
      </material>
    </visual>
    <collision>
      <origin xyz="0.1025 0 0.019" rpy="3.14159 1.5708 0"/>
      <geometry>
        <mesh filename="assets/part_2__3.stl"/>
      </geometry>
    </collision>
    <visual>
      <origin xyz="0.1235 0 -0.001" rpy="3.14159 -0 1.5708"/>
      <geometry>
        <mesh filename="assets/dummy_dc12.stl"/>
      </geometry>
      <material name="dummy_dc12_2_material">
        <color rgba="0.917647 0.917647 0.917647 1"/>
      </material>
    </visual>
    <collision>
      <origin xyz="0.1235 0 -0.001" rpy="3.14159 -0 1.5708"/>
      <geometry>
        <mesh filename="assets/dummy_dc12.stl"/>
      </geometry>
    </collision>
    <visual>
      <origin xyz="-0 0 0.019" rpy="1.5708 1.5708 0"/>
      <geometry>
        <mesh filename="assets/fr12_h101_k.stl"/>
      </geometry>
      <material name="fr12_h101_k_material">
        <color rgba="0.231373 0.380392 0.705882 1"/>
      </material>
    </visual>
    <collision>
      <origin xyz="-0 0 0.019" rpy="1.5708 1.5708 0"/>
      <geometry>
        <mesh filename="assets/fr12_h101_k.stl"/>
      </geometry>
    </collision>
    <visual>
      <origin xyz="0.1025 0 0.019" rpy="3.14159 1.5708 0"/>
      <geometry>
        <mesh filename="assets/fr12_s102_k.stl"/>
      </geometry>
      <material name="fr12_s102_k_2_material">
        <color rgba="0.647059 0.647059 0.647059 1"/>
      </material>
    </visual>
    <collision>
      <origin xyz="0.1025 0 0.019" rpy="3.14159 1.5708 0"/>
      <geometry>
        <mesh filename="assets/fr12_s102_k.stl"/>
      </geometry>
    </collision>
  </link>
  <link name="link4">
    <inertial>
      <origin xyz="0.0309565 0.0323173 0.01895" rpy="0 0 0"/>
      <mass value="0.0954853"/>
      <inertia ixx="2.3308e-05" ixy="-1.60309e-06" ixz="1.4e-11" iyy="3.0851e-05" iyz="5e-12" izz="3.31782e-05"/>
    </inertial>
    <visual>
      <origin xyz="0.0297344 0.0557955 0.018825" rpy="1.21601 -1.5708 0"/>
      <geometry>
        <mesh filename="assets/j4_j5_mirrored.stl"/>
      </geometry>
      <material name="j4_j5_mirrored_material">
        <color rgba="0.537255 0.854902 0.827451 1"/>
      </material>
    </visual>
    <collision>
      <origin xyz="0.0297344 0.0557955 0.018825" rpy="1.21601 -1.5708 0"/>
      <geometry>
        <mesh filename="assets/j4_j5_mirrored.stl"/>
      </geometry>
    </collision>
    <visual>
      <origin xyz="0.0297344 0.0557955 -0.027075" rpy="1.21601 -1.5708 0"/>
      <geometry>
        <mesh filename="assets/j4_j5_mirrored__2.stl"/>
      </geometry>
      <material name="j4_j5_mirrored_2_material">
        <color rgba="0.537255 0.854902 0.827451 1"/>
      </material>
    </visual>
    <collision>
      <origin xyz="0.0297344 0.0557955 -0.027075" rpy="1.21601 -1.5708 0"/>
      <geometry>
        <mesh filename="assets/j4_j5_mirrored__2.stl"/>
      </geometry>
    </collision>
    <visual>
      <origin xyz="0.0297344 0.0557955 0.01895" rpy="-1.21601 1.5708 0"/>
      <geometry>
        <mesh filename="assets/dummy_dc12.stl"/>
      </geometry>
      <material name="dummy_dc12_3_material">
        <color rgba="0.917647 0.917647 0.917647 1"/>
      </material>
    </visual>
    <collision>
      <origin xyz="0.0297344 0.0557955 0.01895" rpy="-1.21601 1.5708 0"/>
      <geometry>
        <mesh filename="assets/dummy_dc12.stl"/>
      </geometry>
    </collision>
  </link>
  <link name="link5">
    <inertial>
      <origin xyz="0.000326575 -0.00076982 -0.0297451" rpy="0 0 0"/>
      <mass value="0.0294484"/>
      <inertia ixx="1.54147e-05" ixy="-5.6056e-08" ixz="2.451e-09" iyy="9.74052e-06" iyz="-5.779e-09" izz="8.03326e-06"/>
    </inertial>
    <visual>
      <origin xyz="0 -0 -0" rpy="-3.14159 -0 1.59462"/>
      <geometry>
        <mesh filename="assets/p01_05_base.stl"/>
      </geometry>
      <material name="p01_05_base_material">
        <color rgba="0.32549 0.317647 0.317647 1"/>
      </material>
    </visual>
    <collision>
      <origin xyz="0 -0 -0" rpy="-3.14159 -0 1.59462"/>
      <geometry>
        <mesh filename="assets/p01_05_base.stl"/>
      </geometry>
    </collision>
    <visual>
      <origin xyz="-4.99858e-05 -1.19092e-06 -0" rpy="-3.14159 -0 1.59462"/>
      <geometry>
        <mesh filename="assets/p01_07_body.stl"/>
      </geometry>
      <material name="p01_07_body_material">
        <color rgba="0.32549 0.317647 0.317647 1"/>
      </material>
    </visual>
    <collision>
      <origin xyz="-4.99858e-05 -1.19092e-06 -0" rpy="-3.14159 -0 1.59462"/>
      <geometry>
        <mesh filename="assets/p01_07_body.stl"/>
      </geometry>
    </collision>
    <visual>
      <origin xyz="4.99858e-05 1.19092e-06 -0" rpy="-3.14159 -0 1.59462"/>
      <geometry>
        <mesh filename="assets/p01_06_body_motor.stl"/>
      </geometry>
      <material name="p01_06_body_motor_material">
        <color rgba="0.32549 0.317647 0.317647 1"/>
      </material>
    </visual>
    <collision>
      <origin xyz="4.99858e-05 1.19092e-06 -0" rpy="-3.14159 -0 1.59462"/>
      <geometry>
        <mesh filename="assets/p01_06_body_motor.stl"/>
      </geometry>
    </collision>
    <visual>
      <origin xyz="-0.0234485 0.0269491 -0.09265" rpy="3.14159 -0 0.0238207"/>
      <geometry>
        <mesh filename="assets/dummy_dc12__2.stl"/>
      </geometry>
      <material name="dummy_dc12_4_material">
        <color rgba="0.917647 0.917647 0.917647 1"/>
      </material>
    </visual>
    <collision>
      <origin xyz="-0.0234485 0.0269491 -0.09265" rpy="3.14159 -0 0.0238207"/>
      <geometry>
        <mesh filename="assets/dummy_dc12__2.stl"/>
      </geometry>
    </collision>
  </link>
  <link name="link6">
    <inertial>
      <origin xyz="-0.00148139 -0.0131112 -0.00445993" rpy="0 0 0"/>
      <mass value="0.00659741"/>
      <inertia ixx="2.745e-06" ixy="1.87617e-07" ixz="5.675e-09" iyy="2.4936e-07" iyz="5.7184e-08" izz="2.90928e-06"/>
    </inertial>
    <visual>
      <origin xyz="-0.019 0.03 -0.00385" rpy="1.5708 -0 -0"/>
      <geometry>
        <mesh filename="assets/p01_01_gearlink_motor.stl"/>
      </geometry>
      <material name="p01_01_gearlink_motor_material">
        <color rgba="0.32549 0.317647 0.317647 1"/>
      </material>
    </visual>
    <collision>
      <origin xyz="-0.019 0.03 -0.00385" rpy="1.5708 -0 -0"/>
      <geometry>
        <mesh filename="assets/p01_01_gearlink_motor.stl"/>
      </geometry>
    </collision>
  </link>
  <joint name="joint_6" type="revolute">
    <origin xyz="0.00349633 0.0190887 -0.03" rpy="1.5708 -0.663391 1.59462"/>
    <parent link="link5"/>
    <child link="link6"/>
    <axis xyz="0 0 1"/>
    <limit effort="10" velocity="10" lower="-0.488858" upper="0.907405"/>
  </joint>
  <link name="link7">
    <inertial>
      <origin xyz="-0.00711347 0.0116656 -0.00388399" rpy="0 0 0"/>
      <mass value="0.00640183"/>
      <inertia ixx="1.57052e-06" ixy="1.237e-06" ixz="-8.3e-11" iyy="1.34561e-06" iyz="-4.52e-10" izz="2.86735e-06"/>
    </inertial>
    <visual>
      <origin xyz="0.033444 -0.0119372 -0.00385" rpy="-1.5708 -0 0.663391"/>
      <geometry>
        <mesh filename="assets/p01_02_gearlink.stl"/>
      </geometry>
      <material name="p01_02_gearlink_material">
        <color rgba="0.32549 0.317647 0.317647 1"/>
      </material>
    </visual>
    <collision>
      <origin xyz="0.033444 -0.0119372 -0.00385" rpy="-1.5708 -0 0.663391"/>
      <geometry>
        <mesh filename="assets/p01_02_gearlink.stl"/>
      </geometry>
    </collision>
  </link>
  <joint name="joint_6_mimic_gear" type="revolute">
    <origin xyz="-0.00349633 -0.0190887 -0.03" rpy="-1.5708 -0 1.59462"/>
    <parent link="link5"/>
    <child link="link7"/>
    <axis xyz="0 0 1"/>
    <limit effort="10" velocity="10" lower="-3.141592653589793" upper="3.141592653589793"/>
    <mimic joint="joint_6" multiplier="1.0"/>
  </joint>
  <link name="link9">
    <inertial>
      <origin xyz="0.0153948 -0.0196977 -0.00385" rpy="0 0 0"/>
      <mass value="0.00411112"/>
      <inertia ixx="7.03097e-07" ixy="5.06875e-07" ixz="-0" iyy="4.50699e-07" iyz="-0" izz="1.11342e-06"/>
    </inertial>
    <visual>
      <origin xyz="0.0746144 -0.0751704 -0.00385" rpy="1.5708 -0 -2.4782"/>
      <geometry>
        <mesh filename="assets/p01_03_link.stl"/>
      </geometry>
      <material name="p01_03_link_material">
        <color rgba="0.32549 0.317647 0.317647 1"/>
      </material>
    </visual>
    <collision>
      <origin xyz="0.0746144 -0.0751704 -0.00385" rpy="1.5708 -0 -2.4782"/>
      <geometry>
        <mesh filename="assets/p01_03_link.stl"/>
      </geometry>
    </collision>
  </link>
  <link name="link10">
    <inertial>
      <origin xyz="0.0182041 -0.0092209 0.004" rpy="0 0 0"/>
      <mass value="0.0165615"/>
      <inertia ixx="3.28447e-06" ixy="3.65718e-06" ixz="-0" iyy="6.3257e-06" iyz="0" izz="8.887e-06"/>
    </inertial>
    <visual>
      <origin xyz="-0.047608 0.0953133 0.004" rpy="-1.5708 0 -2.4782"/>
      <geometry>
        <mesh filename="assets/p01_04_finger.stl"/>
      </geometry>
      <material name="p01_04_finger_material">
        <color rgba="0.32549 0.317647 0.317647 1"/>
      </material>
    </visual>
    <collision>
      <origin xyz="-0.047608 0.0953133 0.004" rpy="-1.5708 0 -2.4782"/>
      <geometry>
        <mesh filename="assets/p01_04_finger.stl"/>
      </geometry>
    </collision>
  </link>
  <link name="link6_2">
    <inertial>
      <origin xyz="-0.00148139 0.0368888 -0.00445993" rpy="0 0 0"/>
      <mass value="0.00659741"/>
      <inertia ixx="2.745e-06" ixy="1.87617e-07" ixz="5.675e-09" iyy="2.4936e-07" iyz="5.7184e-08" izz="2.90928e-06"/>
    </inertial>
    <visual>
      <origin xyz="-0.019 0.08 -0.00385" rpy="1.5708 -0 -0"/>
      <geometry>
        <mesh filename="assets/p01_01_gearlink_motor.stl"/>
      </geometry>
      <material name="p01_01_gearlink_motor_2_material">
        <color rgba="0.32549 0.317647 0.317647 1"/>
      </material>
    </visual>
    <collision>
      <origin xyz="-0.019 0.08 -0.00385" rpy="1.5708 -0 -0"/>
      <geometry>
        <mesh filename="assets/p01_01_gearlink_motor.stl"/>
      </geometry>
    </collision>
  </link>
  <joint name="joint_6_mimic_L2" type="revolute">
    <origin xyz="-0.0206236 0.0158325 0" rpy="3.14159 -0 3.14159"/>
    <parent link="link10"/>
    <child link="link6_2"/>
    <axis xyz="0 0 1"/>
    <limit effort="10" velocity="10" lower="-3.141592653589793" upper="3.141592653589793"/>
  </joint>
  <joint name="joint_6_mimic_L3" type="revolute">
    <origin xyz="0.0307896 -0.0393954 -0" rpy="3.14159 -0 -2.4782"/>
    <parent link="link9"/>
    <child link="link10"/>
    <axis xyz="0 0 1"/>
    <limit effort="10" velocity="10" lower="-3.141592653589793" upper="3.141592653589793"/>
  </joint>
  <joint name="joint_6_mimic_L1" type="revolute">
    <origin xyz="0.00365115 0.0125905 -0.0551744" rpy="1.5708 -0 1.59462"/>
    <parent link="link5"/>
    <child link="link9"/>
    <axis xyz="0 0 1"/>
    <limit effort="10" velocity="10" lower="-3.141592653589793" upper="3.141592653589793"/>
  </joint>
  <link name="link8">
    <inertial>
      <origin xyz="-0.0153948 0.0196977 -0.00385" rpy="0 0 0"/>
      <mass value="0.00411112"/>
      <inertia ixx="7.03097e-07" ixy="5.06875e-07" ixz="0" iyy="4.50699e-07" iyz="0" izz="1.11342e-06"/>
    </inertial>
    <visual>
      <origin xyz="-0.0549167 0.0905652 -0.00385" rpy="-1.5708 0 -2.4782"/>
      <geometry>
        <mesh filename="assets/p01_03_link.stl"/>
      </geometry>
      <material name="p01_03_link_2_material">
        <color rgba="0.32549 0.317647 0.317647 1"/>
      </material>
    </visual>
    <collision>
      <origin xyz="-0.0549167 0.0905652 -0.00385" rpy="-1.5708 0 -2.4782"/>
      <geometry>
        <mesh filename="assets/p01_03_link.stl"/>
      </geometry>
    </collision>
  </link>
  <link name="link11">
    <inertial>
      <origin xyz="-0.00866502 0.0184752 0.004" rpy="0 0 0"/>
      <mass value="0.0165615"/>
      <inertia ixx="7.98655e-06" ixy="2.35914e-06" ixz="0" iyy="1.62362e-06" iyz="-0" izz="8.887e-06"/>
    </inertial>
    <visual>
      <origin xyz="-0.0211824 -0.104415 0.004" rpy="-1.5708 0 -0"/>
      <geometry>
        <mesh filename="assets/p01_04_finger.stl"/>
      </geometry>
      <material name="p01_04_finger_2_material">
        <color rgba="0.32549 0.317647 0.317647 1"/>
      </material>
    </visual>
    <collision>
      <origin xyz="-0.0211824 -0.104415 0.004" rpy="-1.5708 0 -0"/>
      <geometry>
        <mesh filename="assets/p01_04_finger.stl"/>
      </geometry>
    </collision>
  </link>
  <link name="link7_2">
    <inertial>
      <origin xyz="0.00157884 -0.0364281 -0.00388399" rpy="0 0 0"/>
      <mass value="0.00640183"/>
      <inertia ixx="2.68558e-06" ixy="1.89731e-07" ixz="-3.44e-10" iyy="2.30542e-07" iyz="-3.05e-10" izz="2.86735e-06"/>
    </inertial>
    <visual>
      <origin xyz="0.019 -0.08 -0.00385" rpy="-1.5708 0 0"/>
      <geometry>
        <mesh filename="assets/p01_02_gearlink.stl"/>
      </geometry>
      <material name="p01_02_gearlink_2_material">
        <color rgba="0.32549 0.317647 0.317647 1"/>
      </material>
    </visual>
    <collision>
      <origin xyz="0.019 -0.08 -0.00385" rpy="-1.5708 0 0"/>
      <geometry>
        <mesh filename="assets/p01_02_gearlink.stl"/>
      </geometry>
    </collision>
  </link>
  <joint name="joint_6_mimic_R2" type="revolute">
    <origin xyz="0.0065 -0.0251744 0" rpy="3.14159 -0 2.4782"/>
    <parent link="link11"/>
    <child link="link7_2"/>
    <axis xyz="0 0 1"/>
    <limit effort="10" velocity="10" lower="-3.141592653589793" upper="3.141592653589793"/>
  </joint>
  <joint name="joint_6_mimic_R3" type="revolute">
    <origin xyz="-0.0307896 0.0393954 -0" rpy="3.14159 0 3.14159"/>
    <parent link="link8"/>
    <child link="link11"/>
    <axis xyz="0 0 1"/>
    <limit effort="10" velocity="10" lower="-3.141592653589793" upper="3.141592653589793"/>
  </joint>
  <joint name="joint_6_mimic_R1" type="revolute">
    <origin xyz="-0.00365115 -0.0125905 -0.0551744" rpy="-1.5708 -0 1.59462"/>
    <parent link="link5"/>
    <child link="link8"/>
    <axis xyz="0 0 1"/>
    <limit effort="10" velocity="10" lower="-3.141592653589793" upper="3.141592653589793"/>
  </joint>
  <joint name="joint_5" type="revolute">
    <origin xyz="0.029387 0.0548578 0.01895" rpy="-1.5708 -0 2.78681"/>
    <parent link="link4"/>
    <child link="link5"/>
    <axis xyz="0 0 1"/>
    <limit effort="10" velocity="10" lower="-1.59462" upper="1.54698"/>
  </joint>
  <joint name="joint_4" type="revolute">
    <origin xyz="0.1235 0 -0" rpy="0 -0 0"/>
    <parent link="link3"/>
    <child link="link4"/>
    <axis xyz="0 0 1"/>
    <limit effort="10" velocity="10" lower="-1.73961" upper="0.354782"/>
  </joint>
  <joint name="joint_3" type="revolute">
    <origin xyz="0.0326611 -0.148961 0.005544" rpy="-0 -0 -0.172343"/>
    <parent link="link2"/>
    <child link="link3"/>
    <axis xyz="0 0 1"/>
    <limit effort="10" velocity="10" lower="-1.70606" upper="0.388333"/>
  </joint>
  <joint name="joint_2" type="revolute">
    <origin xyz="-0.0017197 0.02444 -0.0458276" rpy="1.5708 0 0.0702486"/>
    <parent link="link1"/>
    <child link="link2"/>
    <axis xyz="0 0 1"/>
    <limit effort="10" velocity="10" lower="-0.215989" upper="1.87841"/>
  </joint>
  <joint name="joint_1" type="revolute">
    <origin xyz="-0.0155 -0 0.059" rpy="3.14159 -0 3.14159"/>
    <parent link="link0"/>
    <child link="link1"/>
    <axis xyz="0 0 1"/>
    <limit effort="10" velocity="10" lower="-1.64104" upper="1.50055"/>
  </joint>
</robot>
